[2024-09-11 17:20:13 +0000] [19606] [INFO] Running on http://0.0.0.0:8877 (CTRL + C to quit)
[2024-09-11 17:20:13 +0000] [19608] [INFO] Running on http://0.0.0.0:8877 (CTRL + C to quit)
[2024-09-11 17:20:13 +0000] [19607] [INFO] Running on http://0.0.0.0:8877 (CTRL + C to quit)
[2024-09-11 17:20:13 +0000] [19609] [INFO] Running on http://0.0.0.0:8877 (CTRL + C to quit)
[2024-09-11 17:21:40 +0000] [21893] [INFO] Running on http://0.0.0.0:8877 (CTRL + C to quit)
[2024-09-11 17:21:40 +0000] [21895] [INFO] Running on http://0.0.0.0:8877 (CTRL + C to quit)
[2024-09-11 17:21:40 +0000] [21891] [INFO] Running on http://0.0.0.0:8877 (CTRL + C to quit)
[2024-09-11 17:21:40 +0000] [21890] [INFO] Running on http://0.0.0.0:8877 (CTRL + C to quit)
[2024-09-11 17:21:40 +0000] [21892] [INFO] Running on http://0.0.0.0:8877 (CTRL + C to quit)
[2024-09-11 17:21:40 +0000] [21889] [INFO] Running on http://0.0.0.0:8877 (CTRL + C to quit)
[2024-09-11 17:21:40 +0000] [21888] [INFO] Running on http://0.0.0.0:8877 (CTRL + C to quit)
[2024-09-11 17:21:40 +0000] [21894] [INFO] Running on http://0.0.0.0:8877 (CTRL + C to quit)
[2024-09-11 17:35:30 +0000] [33479] [INFO] Running on http://0.0.0.0:8877 (CTRL + C to quit)
[2024-09-11 17:35:30 +0000] [33475] [INFO] Running on http://0.0.0.0:8877 (CTRL + C to quit)
[2024-09-11 17:35:31 +0000] [33477] [INFO] Running on http://0.0.0.0:8877 (CTRL + C to quit)
[2024-09-11 17:35:31 +0000] [33478] [INFO] Running on http://0.0.0.0:8877 (CTRL + C to quit)
[2024-09-11 17:35:31 +0000] [33476] [INFO] Running on http://0.0.0.0:8877 (CTRL + C to quit)
[2024-09-11 17:35:31 +0000] [33480] [INFO] Running on http://0.0.0.0:8877 (CTRL + C to quit)
[2024-09-11 17:35:31 +0000] [33482] [INFO] Running on http://0.0.0.0:8877 (CTRL + C to quit)
[2024-09-11 17:35:31 +0000] [33481] [INFO] Running on http://0.0.0.0:8877 (CTRL + C to quit)
[2024-09-11 17:39:48 +0000] [38368] [INFO] Running on http://0.0.0.0:8877 (CTRL + C to quit)
[2024-09-11 17:39:48 +0000] [38364] [INFO] Running on http://0.0.0.0:8877 (CTRL + C to quit)
[2024-09-11 17:39:48 +0000] [38365] [INFO] Running on http://0.0.0.0:8877 (CTRL + C to quit)
[2024-09-11 17:39:48 +0000] [38362] [INFO] Running on http://0.0.0.0:8877 (CTRL + C to quit)
[2024-09-11 17:39:49 +0000] [38363] [INFO] Running on http://0.0.0.0:8877 (CTRL + C to quit)
[2024-09-11 17:39:49 +0000] [38369] [INFO] Running on http://0.0.0.0:8877 (CTRL + C to quit)
[2024-09-11 17:39:49 +0000] [38367] [INFO] Running on http://0.0.0.0:8877 (CTRL + C to quit)
[2024-09-11 17:39:49 +0000] [38366] [INFO] Running on http://0.0.0.0:8877 (CTRL + C to quit)
[2024-09-11 17:40:00 +0000] [39067] [INFO] Running on http://0.0.0.0:8877 (CTRL + C to quit)
[2024-09-11 17:40:00 +0000] [39063] [INFO] Running on http://0.0.0.0:8877 (CTRL + C to quit)
[2024-09-11 17:40:00 +0000] [39066] [INFO] Running on http://0.0.0.0:8877 (CTRL + C to quit)
[2024-09-11 17:40:00 +0000] [39068] [INFO] Running on http://0.0.0.0:8877 (CTRL + C to quit)
[2024-09-11 17:40:00 +0000] [39062] [INFO] Running on http://0.0.0.0:8877 (CTRL + C to quit)
[2024-09-11 17:40:00 +0000] [39065] [INFO] Running on http://0.0.0.0:8877 (CTRL + C to quit)
[2024-09-11 17:40:00 +0000] [39064] [INFO] Running on http://0.0.0.0:8877 (CTRL + C to quit)
[2024-09-11 17:40:00 +0000] [39069] [INFO] Running on http://0.0.0.0:8877 (CTRL + C to quit)
[2024-09-11 17:40:03 +0000] [39669] [INFO] Running on http://0.0.0.0:8877 (CTRL + C to quit)
[2024-09-11 17:40:03 +0000] [39666] [INFO] Running on http://0.0.0.0:8877 (CTRL + C to quit)
[2024-09-11 17:40:03 +0000] [39672] [INFO] Running on http://0.0.0.0:8877 (CTRL + C to quit)
[2024-09-11 17:40:04 +0000] [39668] [INFO] Running on http://0.0.0.0:8877 (CTRL + C to quit)
[2024-09-11 17:40:04 +0000] [39670] [INFO] Running on http://0.0.0.0:8877 (CTRL + C to quit)
[2024-09-11 17:40:04 +0000] [39667] [INFO] Running on http://0.0.0.0:8877 (CTRL + C to quit)
[2024-09-11 17:40:04 +0000] [39665] [INFO] Running on http://0.0.0.0:8877 (CTRL + C to quit)
[2024-09-11 17:40:04 +0000] [39671] [INFO] Running on http://0.0.0.0:8877 (CTRL + C to quit)
[2024-09-11 18:04:10 +0000] [19609] [ERROR] Error in ASGI Framework
Traceback (most recent call last):
  File "/usr/local/src/.venv/lib/python3.12/site-packages/hypercorn/asyncio/task_group.py", line 27, in _handle
    await app(scope, receive, send, sync_spawn, call_soon)
  File "/usr/local/src/.venv/lib/python3.12/site-packages/hypercorn/app_wrappers.py", line 34, in __call__
    await self.app(scope, receive, send)
  File "/usr/local/src/.venv/lib/python3.12/site-packages/quart/app.py", line 1667, in __call__
    await self.asgi_app(scope, receive, send)
  File "/usr/local/src/.venv/lib/python3.12/site-packages/quart/app.py", line 1693, in asgi_app
    await asgi_handler(receive, send)
  File "/usr/local/src/.venv/lib/python3.12/site-packages/quart/asgi.py", line 52, in __call__
    raise_task_exceptions(done)
  File "/usr/local/src/.venv/lib/python3.12/site-packages/quart/utils.py", line 180, in raise_task_exceptions
    raise task.exception()
  File "/usr/local/src/.venv/lib/python3.12/site-packages/quart/asgi.py", line 100, in handle_request
    response = await _handle_exception(self.app, error)
               ^^^^^^^^^^^^^^^^^^^^^^^^^^^^^^^^^^^^^^^^
  File "/usr/local/src/.venv/lib/python3.12/site-packages/quart/asgi.py", line 357, in _handle_exception
    raise error
  File "/usr/local/src/.venv/lib/python3.12/site-packages/quart/asgi.py", line 98, in handle_request
    response = await self.app.handle_request(request)
               ^^^^^^^^^^^^^^^^^^^^^^^^^^^^^^^^^^^^^^
  File "/usr/local/src/.venv/lib/python3.12/site-packages/quart/app.py", line 1401, in handle_request
    async with self.request_context(request) as request_context:
  File "/usr/local/src/.venv/lib/python3.12/site-packages/quart/ctx.py", line 88, in __aexit__
    await self.auto_pop(exc_value)
  File "/usr/local/src/.venv/lib/python3.12/site-packages/quart/ctx.py", line 81, in auto_pop
    await self.pop(exc)
  File "/usr/local/src/.venv/lib/python3.12/site-packages/quart/ctx.py", line 149, in pop
    await self.app.do_teardown_request(exc, self)
  File "/usr/local/src/.venv/lib/python3.12/site-packages/quart/app.py", line 1164, in do_teardown_request
    await self.ensure_async(function)(exc)
  File "/storage/valis_reg/image_selector/app.py", line 317, in teardown_request
    session["current_slide"] = current_slide_index + 1
    ^^^^^^^^^^^^^^^^^^^^^^^^^^^^
  File "/storage/valis_reg/image_selector/app.py", line 76, in save_selected_images
    for slide, data in app.selected_slide_images.items():
RuntimeError: dictionary changed size during iteration
[2024-09-11 18:29:32 +0000] [39671] [ERROR] Error in ASGI Framework
Traceback (most recent call last):
  File "/usr/local/src/.venv/lib/python3.12/site-packages/hypercorn/asyncio/task_group.py", line 27, in _handle
    await app(scope, receive, send, sync_spawn, call_soon)
  File "/usr/local/src/.venv/lib/python3.12/site-packages/hypercorn/app_wrappers.py", line 34, in __call__
    await self.app(scope, receive, send)
  File "/usr/local/src/.venv/lib/python3.12/site-packages/quart/app.py", line 1667, in __call__
    await self.asgi_app(scope, receive, send)
  File "/usr/local/src/.venv/lib/python3.12/site-packages/quart/app.py", line 1693, in asgi_app
    await asgi_handler(receive, send)
  File "/usr/local/src/.venv/lib/python3.12/site-packages/quart/asgi.py", line 52, in __call__
    raise_task_exceptions(done)
  File "/usr/local/src/.venv/lib/python3.12/site-packages/quart/utils.py", line 180, in raise_task_exceptions
    raise task.exception()
  File "/usr/local/src/.venv/lib/python3.12/site-packages/quart/asgi.py", line 100, in handle_request
    response = await _handle_exception(self.app, error)
               ^^^^^^^^^^^^^^^^^^^^^^^^^^^^^^^^^^^^^^^^
  File "/usr/local/src/.venv/lib/python3.12/site-packages/quart/asgi.py", line 357, in _handle_exception
    raise error
  File "/usr/local/src/.venv/lib/python3.12/site-packages/quart/asgi.py", line 98, in handle_request
    response = await self.app.handle_request(request)
               ^^^^^^^^^^^^^^^^^^^^^^^^^^^^^^^^^^^^^^
  File "/usr/local/src/.venv/lib/python3.12/site-packages/quart/app.py", line 1401, in handle_request
    async with self.request_context(request) as request_context:
  File "/usr/local/src/.venv/lib/python3.12/site-packages/quart/ctx.py", line 88, in __aexit__
    await self.auto_pop(exc_value)
  File "/usr/local/src/.venv/lib/python3.12/site-packages/quart/ctx.py", line 81, in auto_pop
    await self.pop(exc)
  File "/usr/local/src/.venv/lib/python3.12/site-packages/quart/ctx.py", line 149, in pop
    await self.app.do_teardown_request(exc, self)
  File "/usr/local/src/.venv/lib/python3.12/site-packages/quart/app.py", line 1164, in do_teardown_request
    await self.ensure_async(function)(exc)
  File "/storage/valis_reg/image_selector/app.py", line 327, in teardown_request
    await save_selected_images()
  File "/storage/valis_reg/image_selector/app.py", line 76, in save_selected_images
    for slide, data in app.selected_slide_images.items():
RuntimeError: dictionary changed size during iteration
[2024-09-12 11:29:05 +0000] [39672] [ERROR] Error in ASGI Framework
Traceback (most recent call last):
  File "/usr/local/src/.venv/lib/python3.12/site-packages/hypercorn/asyncio/task_group.py", line 27, in _handle
    await app(scope, receive, send, sync_spawn, call_soon)
  File "/usr/local/src/.venv/lib/python3.12/site-packages/hypercorn/app_wrappers.py", line 34, in __call__
    await self.app(scope, receive, send)
  File "/usr/local/src/.venv/lib/python3.12/site-packages/quart/app.py", line 1667, in __call__
    await self.asgi_app(scope, receive, send)
  File "/usr/local/src/.venv/lib/python3.12/site-packages/quart/app.py", line 1693, in asgi_app
    await asgi_handler(receive, send)
  File "/usr/local/src/.venv/lib/python3.12/site-packages/quart/asgi.py", line 52, in __call__
    raise_task_exceptions(done)
  File "/usr/local/src/.venv/lib/python3.12/site-packages/quart/utils.py", line 180, in raise_task_exceptions
    raise task.exception()
  File "/usr/local/src/.venv/lib/python3.12/site-packages/quart/asgi.py", line 100, in handle_request
    response = await _handle_exception(self.app, error)
               ^^^^^^^^^^^^^^^^^^^^^^^^^^^^^^^^^^^^^^^^
  File "/usr/local/src/.venv/lib/python3.12/site-packages/quart/asgi.py", line 357, in _handle_exception
    raise error
  File "/usr/local/src/.venv/lib/python3.12/site-packages/quart/asgi.py", line 98, in handle_request
    response = await self.app.handle_request(request)
               ^^^^^^^^^^^^^^^^^^^^^^^^^^^^^^^^^^^^^^
  File "/usr/local/src/.venv/lib/python3.12/site-packages/quart/app.py", line 1401, in handle_request
    async with self.request_context(request) as request_context:
  File "/usr/local/src/.venv/lib/python3.12/site-packages/quart/ctx.py", line 88, in __aexit__
    await self.auto_pop(exc_value)
  File "/usr/local/src/.venv/lib/python3.12/site-packages/quart/ctx.py", line 81, in auto_pop
    await self.pop(exc)
  File "/usr/local/src/.venv/lib/python3.12/site-packages/quart/ctx.py", line 149, in pop
    await self.app.do_teardown_request(exc, self)
  File "/usr/local/src/.venv/lib/python3.12/site-packages/quart/app.py", line 1164, in do_teardown_request
    await self.ensure_async(function)(exc)
  File "/storage/valis_reg/image_selector/app.py", line 327, in teardown_request
    await save_selected_images()
  File "/storage/valis_reg/image_selector/app.py", line 76, in save_selected_images
    for slide, data in app.selected_slide_images.items():
RuntimeError: dictionary changed size during iteration
[2024-09-12 12:38:44 +0000] [19607] [ERROR] Error in ASGI Framework
Traceback (most recent call last):
  File "/usr/local/src/.venv/lib/python3.12/site-packages/hypercorn/asyncio/task_group.py", line 27, in _handle
    await app(scope, receive, send, sync_spawn, call_soon)
  File "/usr/local/src/.venv/lib/python3.12/site-packages/hypercorn/app_wrappers.py", line 34, in __call__
    await self.app(scope, receive, send)
  File "/usr/local/src/.venv/lib/python3.12/site-packages/quart/app.py", line 1667, in __call__
    await self.asgi_app(scope, receive, send)
  File "/usr/local/src/.venv/lib/python3.12/site-packages/quart/app.py", line 1693, in asgi_app
    await asgi_handler(receive, send)
  File "/usr/local/src/.venv/lib/python3.12/site-packages/quart/asgi.py", line 52, in __call__
    raise_task_exceptions(done)
  File "/usr/local/src/.venv/lib/python3.12/site-packages/quart/utils.py", line 180, in raise_task_exceptions
    raise task.exception()
  File "/usr/local/src/.venv/lib/python3.12/site-packages/quart/asgi.py", line 100, in handle_request
    response = await _handle_exception(self.app, error)
               ^^^^^^^^^^^^^^^^^^^^^^^^^^^^^^^^^^^^^^^^
  File "/usr/local/src/.venv/lib/python3.12/site-packages/quart/asgi.py", line 357, in _handle_exception
    raise error
  File "/usr/local/src/.venv/lib/python3.12/site-packages/quart/asgi.py", line 98, in handle_request
    response = await self.app.handle_request(request)
               ^^^^^^^^^^^^^^^^^^^^^^^^^^^^^^^^^^^^^^
  File "/usr/local/src/.venv/lib/python3.12/site-packages/quart/app.py", line 1401, in handle_request
    async with self.request_context(request) as request_context:
  File "/usr/local/src/.venv/lib/python3.12/site-packages/quart/ctx.py", line 88, in __aexit__
    await self.auto_pop(exc_value)
  File "/usr/local/src/.venv/lib/python3.12/site-packages/quart/ctx.py", line 81, in auto_pop
    await self.pop(exc)
  File "/usr/local/src/.venv/lib/python3.12/site-packages/quart/ctx.py", line 149, in pop
    await self.app.do_teardown_request(exc, self)
  File "/usr/local/src/.venv/lib/python3.12/site-packages/quart/app.py", line 1164, in do_teardown_request
    await self.ensure_async(function)(exc)
  File "/storage/valis_reg/image_selector/app.py", line 317, in teardown_request
    session["current_slide"] = current_slide_index + 1
    ^^^^^^^^^^^^^^^^^^^^^^^^^^^^
  File "/storage/valis_reg/image_selector/app.py", line 76, in save_selected_images
    for slide, data in app.selected_slide_images.items():
RuntimeError: dictionary changed size during iteration
[2024-09-12 14:41:35 +0000] [39671] [ERROR] Error in ASGI Framework
Traceback (most recent call last):
  File "/usr/local/src/.venv/lib/python3.12/site-packages/hypercorn/asyncio/task_group.py", line 27, in _handle
    await app(scope, receive, send, sync_spawn, call_soon)
  File "/usr/local/src/.venv/lib/python3.12/site-packages/hypercorn/app_wrappers.py", line 34, in __call__
    await self.app(scope, receive, send)
  File "/usr/local/src/.venv/lib/python3.12/site-packages/quart/app.py", line 1667, in __call__
    await self.asgi_app(scope, receive, send)
  File "/usr/local/src/.venv/lib/python3.12/site-packages/quart/app.py", line 1693, in asgi_app
    await asgi_handler(receive, send)
  File "/usr/local/src/.venv/lib/python3.12/site-packages/quart/asgi.py", line 52, in __call__
    raise_task_exceptions(done)
  File "/usr/local/src/.venv/lib/python3.12/site-packages/quart/utils.py", line 180, in raise_task_exceptions
    raise task.exception()
  File "/usr/local/src/.venv/lib/python3.12/site-packages/quart/asgi.py", line 100, in handle_request
    response = await _handle_exception(self.app, error)
               ^^^^^^^^^^^^^^^^^^^^^^^^^^^^^^^^^^^^^^^^
  File "/usr/local/src/.venv/lib/python3.12/site-packages/quart/asgi.py", line 357, in _handle_exception
    raise error
  File "/usr/local/src/.venv/lib/python3.12/site-packages/quart/asgi.py", line 98, in handle_request
    response = await self.app.handle_request(request)
               ^^^^^^^^^^^^^^^^^^^^^^^^^^^^^^^^^^^^^^
  File "/usr/local/src/.venv/lib/python3.12/site-packages/quart/app.py", line 1401, in handle_request
    async with self.request_context(request) as request_context:
  File "/usr/local/src/.venv/lib/python3.12/site-packages/quart/ctx.py", line 88, in __aexit__
    await self.auto_pop(exc_value)
  File "/usr/local/src/.venv/lib/python3.12/site-packages/quart/ctx.py", line 81, in auto_pop
    await self.pop(exc)
  File "/usr/local/src/.venv/lib/python3.12/site-packages/quart/ctx.py", line 149, in pop
    await self.app.do_teardown_request(exc, self)
  File "/usr/local/src/.venv/lib/python3.12/site-packages/quart/app.py", line 1164, in do_teardown_request
    await self.ensure_async(function)(exc)
  File "/storage/valis_reg/image_selector/app.py", line 327, in teardown_request
    await save_selected_images()
  File "/storage/valis_reg/image_selector/app.py", line 76, in save_selected_images
    for slide, data in app.selected_slide_images.items():
RuntimeError: dictionary changed size during iteration
[2024-09-12 14:41:36 +0000] [39671] [ERROR] Error in ASGI Framework
Traceback (most recent call last):
  File "/usr/local/src/.venv/lib/python3.12/site-packages/hypercorn/asyncio/task_group.py", line 27, in _handle
    await app(scope, receive, send, sync_spawn, call_soon)
  File "/usr/local/src/.venv/lib/python3.12/site-packages/hypercorn/app_wrappers.py", line 34, in __call__
    await self.app(scope, receive, send)
  File "/usr/local/src/.venv/lib/python3.12/site-packages/quart/app.py", line 1667, in __call__
    await self.asgi_app(scope, receive, send)
  File "/usr/local/src/.venv/lib/python3.12/site-packages/quart/app.py", line 1693, in asgi_app
    await asgi_handler(receive, send)
  File "/usr/local/src/.venv/lib/python3.12/site-packages/quart/asgi.py", line 52, in __call__
    raise_task_exceptions(done)
  File "/usr/local/src/.venv/lib/python3.12/site-packages/quart/utils.py", line 180, in raise_task_exceptions
    raise task.exception()
  File "/usr/local/src/.venv/lib/python3.12/site-packages/quart/asgi.py", line 100, in handle_request
    response = await _handle_exception(self.app, error)
               ^^^^^^^^^^^^^^^^^^^^^^^^^^^^^^^^^^^^^^^^
  File "/usr/local/src/.venv/lib/python3.12/site-packages/quart/asgi.py", line 357, in _handle_exception
    raise error
  File "/usr/local/src/.venv/lib/python3.12/site-packages/quart/asgi.py", line 98, in handle_request
    response = await self.app.handle_request(request)
               ^^^^^^^^^^^^^^^^^^^^^^^^^^^^^^^^^^^^^^
  File "/usr/local/src/.venv/lib/python3.12/site-packages/quart/app.py", line 1401, in handle_request
    async with self.request_context(request) as request_context:
  File "/usr/local/src/.venv/lib/python3.12/site-packages/quart/ctx.py", line 88, in __aexit__
    await self.auto_pop(exc_value)
  File "/usr/local/src/.venv/lib/python3.12/site-packages/quart/ctx.py", line 81, in auto_pop
    await self.pop(exc)
  File "/usr/local/src/.venv/lib/python3.12/site-packages/quart/ctx.py", line 149, in pop
    await self.app.do_teardown_request(exc, self)
  File "/usr/local/src/.venv/lib/python3.12/site-packages/quart/app.py", line 1164, in do_teardown_request
    await self.ensure_async(function)(exc)
  File "/storage/valis_reg/image_selector/app.py", line 327, in teardown_request
    await save_selected_images()
  File "/storage/valis_reg/image_selector/app.py", line 76, in save_selected_images
    for slide, data in app.selected_slide_images.items():
RuntimeError: dictionary changed size during iteration
[2024-09-12 14:53:05 +0000] [39671] [ERROR] Error in ASGI Framework
Traceback (most recent call last):
  File "/usr/local/src/.venv/lib/python3.12/site-packages/hypercorn/asyncio/task_group.py", line 27, in _handle
    await app(scope, receive, send, sync_spawn, call_soon)
  File "/usr/local/src/.venv/lib/python3.12/site-packages/hypercorn/app_wrappers.py", line 34, in __call__
    await self.app(scope, receive, send)
  File "/usr/local/src/.venv/lib/python3.12/site-packages/quart/app.py", line 1667, in __call__
    await self.asgi_app(scope, receive, send)
  File "/usr/local/src/.venv/lib/python3.12/site-packages/quart/app.py", line 1693, in asgi_app
    await asgi_handler(receive, send)
  File "/usr/local/src/.venv/lib/python3.12/site-packages/quart/asgi.py", line 52, in __call__
    raise_task_exceptions(done)
  File "/usr/local/src/.venv/lib/python3.12/site-packages/quart/utils.py", line 180, in raise_task_exceptions
    raise task.exception()
  File "/usr/local/src/.venv/lib/python3.12/site-packages/quart/asgi.py", line 100, in handle_request
    response = await _handle_exception(self.app, error)
               ^^^^^^^^^^^^^^^^^^^^^^^^^^^^^^^^^^^^^^^^
  File "/usr/local/src/.venv/lib/python3.12/site-packages/quart/asgi.py", line 357, in _handle_exception
    raise error
  File "/usr/local/src/.venv/lib/python3.12/site-packages/quart/asgi.py", line 98, in handle_request
    response = await self.app.handle_request(request)
               ^^^^^^^^^^^^^^^^^^^^^^^^^^^^^^^^^^^^^^
  File "/usr/local/src/.venv/lib/python3.12/site-packages/quart/app.py", line 1401, in handle_request
    async with self.request_context(request) as request_context:
  File "/usr/local/src/.venv/lib/python3.12/site-packages/quart/ctx.py", line 88, in __aexit__
    await self.auto_pop(exc_value)
  File "/usr/local/src/.venv/lib/python3.12/site-packages/quart/ctx.py", line 81, in auto_pop
    await self.pop(exc)
  File "/usr/local/src/.venv/lib/python3.12/site-packages/quart/ctx.py", line 149, in pop
    await self.app.do_teardown_request(exc, self)
  File "/usr/local/src/.venv/lib/python3.12/site-packages/quart/app.py", line 1164, in do_teardown_request
    await self.ensure_async(function)(exc)
  File "/storage/valis_reg/image_selector/app.py", line 327, in teardown_request
    await save_selected_images()
  File "/storage/valis_reg/image_selector/app.py", line 76, in save_selected_images
    for slide, data in app.selected_slide_images.items():
RuntimeError: dictionary changed size during iteration
[2024-09-12 14:58:24 +0000] [39671] [ERROR] Error in ASGI Framework
Traceback (most recent call last):
  File "/usr/local/src/.venv/lib/python3.12/site-packages/hypercorn/asyncio/task_group.py", line 27, in _handle
    await app(scope, receive, send, sync_spawn, call_soon)
  File "/usr/local/src/.venv/lib/python3.12/site-packages/hypercorn/app_wrappers.py", line 34, in __call__
    await self.app(scope, receive, send)
  File "/usr/local/src/.venv/lib/python3.12/site-packages/quart/app.py", line 1667, in __call__
    await self.asgi_app(scope, receive, send)
  File "/usr/local/src/.venv/lib/python3.12/site-packages/quart/app.py", line 1693, in asgi_app
    await asgi_handler(receive, send)
  File "/usr/local/src/.venv/lib/python3.12/site-packages/quart/asgi.py", line 52, in __call__
    raise_task_exceptions(done)
  File "/usr/local/src/.venv/lib/python3.12/site-packages/quart/utils.py", line 180, in raise_task_exceptions
    raise task.exception()
  File "/usr/local/src/.venv/lib/python3.12/site-packages/quart/asgi.py", line 100, in handle_request
    response = await _handle_exception(self.app, error)
               ^^^^^^^^^^^^^^^^^^^^^^^^^^^^^^^^^^^^^^^^
  File "/usr/local/src/.venv/lib/python3.12/site-packages/quart/asgi.py", line 357, in _handle_exception
    raise error
  File "/usr/local/src/.venv/lib/python3.12/site-packages/quart/asgi.py", line 98, in handle_request
    response = await self.app.handle_request(request)
               ^^^^^^^^^^^^^^^^^^^^^^^^^^^^^^^^^^^^^^
  File "/usr/local/src/.venv/lib/python3.12/site-packages/quart/app.py", line 1401, in handle_request
    async with self.request_context(request) as request_context:
  File "/usr/local/src/.venv/lib/python3.12/site-packages/quart/ctx.py", line 88, in __aexit__
    await self.auto_pop(exc_value)
  File "/usr/local/src/.venv/lib/python3.12/site-packages/quart/ctx.py", line 81, in auto_pop
    await self.pop(exc)
  File "/usr/local/src/.venv/lib/python3.12/site-packages/quart/ctx.py", line 149, in pop
    await self.app.do_teardown_request(exc, self)
  File "/usr/local/src/.venv/lib/python3.12/site-packages/quart/app.py", line 1164, in do_teardown_request
    await self.ensure_async(function)(exc)
  File "/storage/valis_reg/image_selector/app.py", line 327, in teardown_request
    await save_selected_images()
  File "/storage/valis_reg/image_selector/app.py", line 76, in save_selected_images
    for slide, data in app.selected_slide_images.items():
RuntimeError: dictionary changed size during iteration
[2024-09-12 15:05:30 +0000] [19609] [ERROR] Error in ASGI Framework
Traceback (most recent call last):
  File "/usr/local/src/.venv/lib/python3.12/site-packages/hypercorn/asyncio/task_group.py", line 27, in _handle
    await app(scope, receive, send, sync_spawn, call_soon)
  File "/usr/local/src/.venv/lib/python3.12/site-packages/hypercorn/app_wrappers.py", line 34, in __call__
    await self.app(scope, receive, send)
  File "/usr/local/src/.venv/lib/python3.12/site-packages/quart/app.py", line 1667, in __call__
    await self.asgi_app(scope, receive, send)
  File "/usr/local/src/.venv/lib/python3.12/site-packages/quart/app.py", line 1693, in asgi_app
    await asgi_handler(receive, send)
  File "/usr/local/src/.venv/lib/python3.12/site-packages/quart/asgi.py", line 52, in __call__
    raise_task_exceptions(done)
  File "/usr/local/src/.venv/lib/python3.12/site-packages/quart/utils.py", line 180, in raise_task_exceptions
    raise task.exception()
  File "/usr/local/src/.venv/lib/python3.12/site-packages/quart/asgi.py", line 100, in handle_request
    response = await _handle_exception(self.app, error)
               ^^^^^^^^^^^^^^^^^^^^^^^^^^^^^^^^^^^^^^^^
  File "/usr/local/src/.venv/lib/python3.12/site-packages/quart/asgi.py", line 357, in _handle_exception
    raise error
  File "/usr/local/src/.venv/lib/python3.12/site-packages/quart/asgi.py", line 98, in handle_request
    response = await self.app.handle_request(request)
               ^^^^^^^^^^^^^^^^^^^^^^^^^^^^^^^^^^^^^^
  File "/usr/local/src/.venv/lib/python3.12/site-packages/quart/app.py", line 1401, in handle_request
    async with self.request_context(request) as request_context:
  File "/usr/local/src/.venv/lib/python3.12/site-packages/quart/ctx.py", line 88, in __aexit__
    await self.auto_pop(exc_value)
  File "/usr/local/src/.venv/lib/python3.12/site-packages/quart/ctx.py", line 81, in auto_pop
    await self.pop(exc)
  File "/usr/local/src/.venv/lib/python3.12/site-packages/quart/ctx.py", line 149, in pop
    await self.app.do_teardown_request(exc, self)
  File "/usr/local/src/.venv/lib/python3.12/site-packages/quart/app.py", line 1164, in do_teardown_request
    await self.ensure_async(function)(exc)
  File "/storage/valis_reg/image_selector/app.py", line 317, in teardown_request
    session["current_slide"] = current_slide_index + 1
    ^^^^^^^^^^^^^^^^^^^^^^^^^^^^
  File "/storage/valis_reg/image_selector/app.py", line 76, in save_selected_images
    for slide, data in app.selected_slide_images.items():
RuntimeError: dictionary changed size during iteration
[2024-09-12 15:06:03 +0000] [19609] [ERROR] Error in ASGI Framework
Traceback (most recent call last):
  File "/usr/local/src/.venv/lib/python3.12/site-packages/hypercorn/asyncio/task_group.py", line 27, in _handle
    await app(scope, receive, send, sync_spawn, call_soon)
  File "/usr/local/src/.venv/lib/python3.12/site-packages/hypercorn/app_wrappers.py", line 34, in __call__
    await self.app(scope, receive, send)
  File "/usr/local/src/.venv/lib/python3.12/site-packages/quart/app.py", line 1667, in __call__
    await self.asgi_app(scope, receive, send)
  File "/usr/local/src/.venv/lib/python3.12/site-packages/quart/app.py", line 1693, in asgi_app
    await asgi_handler(receive, send)
  File "/usr/local/src/.venv/lib/python3.12/site-packages/quart/asgi.py", line 52, in __call__
    raise_task_exceptions(done)
  File "/usr/local/src/.venv/lib/python3.12/site-packages/quart/utils.py", line 180, in raise_task_exceptions
    raise task.exception()
  File "/usr/local/src/.venv/lib/python3.12/site-packages/quart/asgi.py", line 100, in handle_request
    response = await _handle_exception(self.app, error)
               ^^^^^^^^^^^^^^^^^^^^^^^^^^^^^^^^^^^^^^^^
  File "/usr/local/src/.venv/lib/python3.12/site-packages/quart/asgi.py", line 357, in _handle_exception
    raise error
  File "/usr/local/src/.venv/lib/python3.12/site-packages/quart/asgi.py", line 98, in handle_request
    response = await self.app.handle_request(request)
               ^^^^^^^^^^^^^^^^^^^^^^^^^^^^^^^^^^^^^^
  File "/usr/local/src/.venv/lib/python3.12/site-packages/quart/app.py", line 1401, in handle_request
    async with self.request_context(request) as request_context:
  File "/usr/local/src/.venv/lib/python3.12/site-packages/quart/ctx.py", line 88, in __aexit__
    await self.auto_pop(exc_value)
  File "/usr/local/src/.venv/lib/python3.12/site-packages/quart/ctx.py", line 81, in auto_pop
    await self.pop(exc)
  File "/usr/local/src/.venv/lib/python3.12/site-packages/quart/ctx.py", line 149, in pop
    await self.app.do_teardown_request(exc, self)
  File "/usr/local/src/.venv/lib/python3.12/site-packages/quart/app.py", line 1164, in do_teardown_request
    await self.ensure_async(function)(exc)
  File "/storage/valis_reg/image_selector/app.py", line 317, in teardown_request
    session["current_slide"] = current_slide_index + 1
    ^^^^^^^^^^^^^^^^^^^^^^^^^^^^
  File "/storage/valis_reg/image_selector/app.py", line 76, in save_selected_images
    for slide, data in app.selected_slide_images.items():
RuntimeError: dictionary changed size during iteration
[2024-09-12 15:06:35 +0000] [19609] [ERROR] Error in ASGI Framework
Traceback (most recent call last):
  File "/usr/local/src/.venv/lib/python3.12/site-packages/hypercorn/asyncio/task_group.py", line 27, in _handle
    await app(scope, receive, send, sync_spawn, call_soon)
  File "/usr/local/src/.venv/lib/python3.12/site-packages/hypercorn/app_wrappers.py", line 34, in __call__
    await self.app(scope, receive, send)
  File "/usr/local/src/.venv/lib/python3.12/site-packages/quart/app.py", line 1667, in __call__
    await self.asgi_app(scope, receive, send)
  File "/usr/local/src/.venv/lib/python3.12/site-packages/quart/app.py", line 1693, in asgi_app
    await asgi_handler(receive, send)
  File "/usr/local/src/.venv/lib/python3.12/site-packages/quart/asgi.py", line 52, in __call__
    raise_task_exceptions(done)
  File "/usr/local/src/.venv/lib/python3.12/site-packages/quart/utils.py", line 180, in raise_task_exceptions
    raise task.exception()
  File "/usr/local/src/.venv/lib/python3.12/site-packages/quart/asgi.py", line 100, in handle_request
    response = await _handle_exception(self.app, error)
               ^^^^^^^^^^^^^^^^^^^^^^^^^^^^^^^^^^^^^^^^
  File "/usr/local/src/.venv/lib/python3.12/site-packages/quart/asgi.py", line 357, in _handle_exception
    raise error
  File "/usr/local/src/.venv/lib/python3.12/site-packages/quart/asgi.py", line 98, in handle_request
    response = await self.app.handle_request(request)
               ^^^^^^^^^^^^^^^^^^^^^^^^^^^^^^^^^^^^^^
  File "/usr/local/src/.venv/lib/python3.12/site-packages/quart/app.py", line 1401, in handle_request
    async with self.request_context(request) as request_context:
  File "/usr/local/src/.venv/lib/python3.12/site-packages/quart/ctx.py", line 88, in __aexit__
    await self.auto_pop(exc_value)
  File "/usr/local/src/.venv/lib/python3.12/site-packages/quart/ctx.py", line 81, in auto_pop
    await self.pop(exc)
  File "/usr/local/src/.venv/lib/python3.12/site-packages/quart/ctx.py", line 149, in pop
    await self.app.do_teardown_request(exc, self)
  File "/usr/local/src/.venv/lib/python3.12/site-packages/quart/app.py", line 1164, in do_teardown_request
    await self.ensure_async(function)(exc)
  File "/storage/valis_reg/image_selector/app.py", line 317, in teardown_request
    session["current_slide"] = current_slide_index + 1
    ^^^^^^^^^^^^^^^^^^^^^^^^^^^^
  File "/storage/valis_reg/image_selector/app.py", line 76, in save_selected_images
    for slide, data in app.selected_slide_images.items():
RuntimeError: dictionary changed size during iteration
[2024-09-12 15:11:17 +0000] [19607] [ERROR] Error in ASGI Framework
Traceback (most recent call last):
  File "/usr/local/src/.venv/lib/python3.12/site-packages/hypercorn/asyncio/task_group.py", line 27, in _handle
    await app(scope, receive, send, sync_spawn, call_soon)
  File "/usr/local/src/.venv/lib/python3.12/site-packages/hypercorn/app_wrappers.py", line 34, in __call__
    await self.app(scope, receive, send)
  File "/usr/local/src/.venv/lib/python3.12/site-packages/quart/app.py", line 1667, in __call__
    await self.asgi_app(scope, receive, send)
  File "/usr/local/src/.venv/lib/python3.12/site-packages/quart/app.py", line 1693, in asgi_app
    await asgi_handler(receive, send)
  File "/usr/local/src/.venv/lib/python3.12/site-packages/quart/asgi.py", line 52, in __call__
    raise_task_exceptions(done)
  File "/usr/local/src/.venv/lib/python3.12/site-packages/quart/utils.py", line 180, in raise_task_exceptions
    raise task.exception()
  File "/usr/local/src/.venv/lib/python3.12/site-packages/quart/asgi.py", line 100, in handle_request
    response = await _handle_exception(self.app, error)
               ^^^^^^^^^^^^^^^^^^^^^^^^^^^^^^^^^^^^^^^^
  File "/usr/local/src/.venv/lib/python3.12/site-packages/quart/asgi.py", line 357, in _handle_exception
    raise error
  File "/usr/local/src/.venv/lib/python3.12/site-packages/quart/asgi.py", line 98, in handle_request
    response = await self.app.handle_request(request)
               ^^^^^^^^^^^^^^^^^^^^^^^^^^^^^^^^^^^^^^
  File "/usr/local/src/.venv/lib/python3.12/site-packages/quart/app.py", line 1401, in handle_request
    async with self.request_context(request) as request_context:
  File "/usr/local/src/.venv/lib/python3.12/site-packages/quart/ctx.py", line 88, in __aexit__
    await self.auto_pop(exc_value)
  File "/usr/local/src/.venv/lib/python3.12/site-packages/quart/ctx.py", line 81, in auto_pop
    await self.pop(exc)
  File "/usr/local/src/.venv/lib/python3.12/site-packages/quart/ctx.py", line 149, in pop
    await self.app.do_teardown_request(exc, self)
  File "/usr/local/src/.venv/lib/python3.12/site-packages/quart/app.py", line 1164, in do_teardown_request
    await self.ensure_async(function)(exc)
  File "/storage/valis_reg/image_selector/app.py", line 317, in teardown_request
    session["current_slide"] = current_slide_index + 1
    ^^^^^^^^^^^^^^^^^^^^^^^^^^^^
  File "/storage/valis_reg/image_selector/app.py", line 76, in save_selected_images
    for slide, data in app.selected_slide_images.items():
RuntimeError: dictionary changed size during iteration
